Workbook

Sheet Foglio1
A1: Pag. 1 di 2 | AO1: Geo-Labor s.a.s.
A2: =Foglio2!A2 -> VERBALE ACCETTAZIONE NR: 40/02.04.2026
A3: KORNGROSSENANALYSE (GEMÄß: UNI CEN ISO/TS 17892-4) | AX3: Via del Garda, 46/L - Tel. 0464913102
A4: ANALISI GRANULOMETRICA (NORMA: UNI CEN ISO/TS 17892-4) | AS4: 38068 - Rovereto (TN)
A5: =Foglio2!A10 -> AUFTRAGGEBER/COMMITT.: | L5: =Foglio2!D10 -> Rainerbau | AH5: =Foglio2!A14 -> BOHRUNG/SONDAGGIO:
A6: =Foglio2!A11 -> BEZUG/RIF.: | L6: =Foglio2!D11 -> Dr. Ing. C. Staggl | AH6: =Foglio2!A15 -> PROBE/CAMP.: | AR6: =Foglio2!D15 -> 1
A7: =Foglio2!A12 -> ORT/LOCALITA': | L7: =Foglio2!D12 -> Comune di Valle Aurina (BZ) | AH7: =Foglio2!A16 -> TIEFE/PROF. m: | AR7: =Foglio2!D16 -> \
A8: =Foglio2!A13 -> PROJEKT/PROG.: | L8: =Foglio2!D13 -> Ampliamento della pista ciclabile, tratto B. incrocio via Gföllberg fino incrocio Jahrlboden
A9: =Foglio2!A17 -> BESCHREIBUNG/DESCRIZIONE: | L9: =Foglio2!D17 -> sabbia limosa di colore bianco, con ghiaia spigolosa (marmo di Racines).
A10: ARGILLA | G10: LIMO | T10: SABBIA | AH10: GHIAIA | AU10: CIOTTOLI
G11: Fine | K11: Medio | O11: Grosso | T11: Fine | Y11: Medio | AC11: Grosso | AH11: Fine | AL11: Medio | AQ11: Grosso
F12: 0.002 | J12: 0.006 | S12: 0.06 | X12: 0.2 | AG12: 2 | AK12: 6 | AP12: 20 | AT12: 60
A40: =Foglio2!A48 -> BESCHEINIGUNG/CERTIFICAZIONE NR.: | N40: =Foglio2!E48 -> 40/ | V40: =Foglio2!E53 -> SPERIMENTATORE | AS40: =Foglio2!H53 -> DIRETTORE LABORATORIO
A41: =Foglio2!A49 -> ANNAHMEDATUM/DATA ACCETTAZIONE: | N41: =Foglio2!E49 -> 46114 | X41: =Foglio2!E54 -> R. Mattuzzi | AS41: =Foglio2!H54 -> dr. F. Shams
A42: =Foglio2!A50 -> VERSUCH DATUM/DATA PROVA : | N42: =Foglio2!E50 -> 46115

Sheet Foglio2
A1: Pag. 2 di 2 | F1: Geo-Labor s.a.s.
A2: VERBALE ACCETTAZIONE NR: 40/02.04.2026
I3: Via del Garda, 46L - tel. 0464913102
H4: 38068 - Rovereto (TN)
A5: KORNGROSSENANALYSE (GEMÄß: UNI CEN ISO/TS 17892-4)
A6: ANALISI GRANULOMETRICA (NORMA: UNI CEN ISO/TS 17892-4)
A8: TABELLA RIASSUNTIVA
A10: AUFTRAGGEBER/COMMITT.: | D10: Rainerbau
A11: BEZUG/RIF.: | D11: Dr. Ing. C. Staggl
A12: ORT/LOCALITA': | D12: Comune di Valle Aurina (BZ)
A13: PROJEKT/PROG.: | D13: Ampliamento della pista ciclabile, tratto B. incrocio via Gföllberg fino incrocio Jahrlboden
A14: BOHRUNG/SONDAGGIO:
A15: PROBE/CAMP.: | D15: 1
A16: TIEFE/PROF. m: | D16: \
A17: BESCHREIBUNG/DESCRIZIONE: | D17: sabbia limosa di colore bianco, con ghiaia spigolosa (marmo di Racines).
A20: SIEBUG/SETACCIATURA
A21: Sieb | B21: Durchmesser | D21: Rückstand | E21: Rückstand | F21: Durchgang
A22: Setaccio | B22: Diametro (mm) | D22: Trattenuto (g) | E22: Trattenuto (%) | F22: Passante (%)
A23: 3. 1/2" | B23: 90
A24: 2. 1/2" | B24: 63
A25: 2. 1/4" | B25: 56
A26: 1. 3/4" | B26: 45
A27: 1.1/4" | B27: 31.5
A28: 7/8" | B28: 22.4
A29: 5/8" | B29: 16
A30: 7/16" | B30: 11.2 | D30: 0 | E30: =IF(D30="","",SUM($D$23:D30)/$D$41*100) -> 0 | F30: =IF(D30="",F29,100-$E30) -> 100
A31: 5/16" | B31: 8 | D31: 4.6 | E31: =IF(D31="","",SUM($D$23:D31)/$D$41*100) -> 0.23745612 | F31: =IF(D31="",F30,100-$E31) -> 99.762544
A32: 3.5 | B32: 5.6 | D32: 47.8 | E32: =IF(D32="","",SUM($D$23:D32)/$D$41*100) -> 2.704935 | F32: =IF(D32="",F31,100-$E32) -> 97.295065
A33: 5 | B33: 4 | D33: 128.2 | E33: =IF(D33="","",SUM($D$23:D33)/$D$41*100) -> 9.3227338 | F33: =IF(D33="",F32,100-$E33) -> 90.677266
A34: 10 | B34: 2 | D34: 302.4 | E34: =IF(D34="","",SUM($D$23:D34)/$D$41*100) -> 24.932893 | F34: =IF(D34="",F33,100-$E34) -> 75.067107
A35: 18 | B35: 1 | D35: 295.8 | E35: =IF(D35="","",SUM($D$23:D35)/$D$41*100) -> 40.202354 | F35: =IF(D35="",F34,100-$E35) -> 59.797646
A36: 35 | B36: 0.5 | D36: 282.2 | E36: =IF(D36="","",SUM($D$23:D36)/$D$41*100) -> 54.769771 | F36: =IF(D36="",F35,100-$E36) -> 45.230229
A37: 60 | B37: 0.25 | D37: 243 | E37: =IF(D37="","",SUM($D$23:D37)/$D$41*100) -> 67.313649 | F37: =IF(D37="",F36,100-$E37) -> 32.686351
A38: 120 | B38: 0.125 | D38: 214.4 | E38: =IF(D38="","",SUM($D$23:D38)/$D$41*100) -> 78.381169 | F38: =IF(D38="",F37,100-$E38) -> 21.618831
A39: 230 | B39: 0.063 | D39: 79.4 | E39: =IF(D39="","",SUM($D$23:D39)/$D$41*100) -> 82.479868 | F39: =IF(D39="",F38,100-$E39) -> 17.520132
B40: < 0.063 | D40: =D41-SUM(D23:D39) -> 339.4 | F40: =D40/D41*100 -> 17.520132
A41: Trockenmasse (g) | D41: 1937.2 | E41: Peso secco iniziale (g)
A42: Steine/Ciottoli | B42: =E24 -> 0 | D42: % | E42: D10 mm =
A43: Kies/Ghiaia | B43: =E34-B42 -> 24.932893 | D43: % | E43: D30 mm = | F43: 0.21
A44: Sand/Sabbia | B44: =E39-E34 -> 57.546975 | D44: % | E44: D60 mm = | F44: 1.05
...

Sheet Foglio3
A4: DETERMINAZIONE DELLA GRANULOMETRIA DI UN AGGREGATO
A5: Norma UNI EN 933-1, UNI CEN ISO TS 17892-4
A7: =Foglio2!A2 -> VERBALE ACCETTAZIONE NR: 40/02.04.2026
G8: Data arrivo______________ | H8: =Foglio2!E49 -> 46114
D9: Campione____________ | E9: =Foglio2!D15 -> 1
A10: Sperimentatore_________________ | G10: Data prove______________
A13: Quantità del campione in prova: | G13: m 1 PNS: | H13: =H14+H15 -> #DIV/0!
A14: Massa della frazione grossa ≥ 8,00 mm.: | G14: m 2 PNS: | H14: =SUM(Foglio2!D23:D31) -> 4.6
A15: Massa della frazione fine ≤ 8,00 mm: | F15: =E46 -> #DIV/0! | G15: m 3 PNS: | H15: =E15+F15 -> #DIV/0!
A16: Massa del campione ottenuto dopo quartatura: | G16: m 4 PNS: | H16: =H36-H35 -> 0
A19: Setaccio | B19: Massa trattenuta | E19: Note
A20: mm. | B20: M (g) | D20: M. tot. (A) g
A21: 5.6 | D21: =B21*($H$15/$H$16) -> #DIV/0!
A22: 4 | D22: =B22*($H$15/$H$16) -> #DIV/0!
A23: 2 | D23: =B23*($H$15/$H$16) -> #DIV/0! | E23: Ridurre il passante allo staccio ≤ 8,00 a circa 1000 gr
A24: 1 | D24: =B24*($H$15/$H$16) -> #DIV/0! | E24: (solo se il passante è maggiore di 1000 grammi)
A25: 0.5 | D25: =B25*($H$15/$H$16) -> #DIV/0!
A26: 0.25 | D26: =B26*($H$15/$H$16) -> #DIV/0!
A27: 0.125 | D27: =B27*($H$15/$H$16) -> #DIV/0!
A28: 0.063 | D28: =B28*($H$15/$H$16) -> #DIV/0!
A29: ≤ 0,063 | B29: =H16-SUM(B21:C28) -> 0 | D29: =B29*($H$15/$H$16) -> #DIV/0! | E29: (A): Massa totale trattenuta a ciascun setaccio:
A30: Somma g | E30: M*(M3/M4) = M tot.
A31: Perdita g
A33: PNU > 8mm: | G33: PNU Quartato < 8mm: | H33: =H34-H35 -> 0
A34: PNU < 8mm: | G34: PLU Quartato < 8mm:
A35: PNU Totale: | C35: =C33+C34 -> 0 | G35: tara:
G36: PLS Quartato < 8mm:
A37: Note:___________________________________________________________________________________
G39: %W < 8 mm = | H39: =((H34-H36)/H16)*100 -> #DIV/0!
G40: %W totale = | H40: =((C35-H13)/H13)*100 -> #DIV/0!
B41: Calcolo proporzione per Tot. SECCO <8mm =
B43: PNU < 8mm X m 4 PNS | D43: = | E43: Massa secca della frazione fine < 8,00 mm
B44: PNU Quartato < 8mm
C46: =C34*H16 -> 0 | D46: = | E46: =C46/C47 -> #DIV/0!
C47: =H33 -> 0
A50: gra-terre 0-8 | H50: Geo-Labor sas
