Workbook

Sheet Foglio1
A1: Pag 1 di 2 | AP1: Geo-Labor s.a.s.
A2: =Foglio2!A2 -> VERBALE ACCETTAZIONE NR: 22/27.02.2026
AZ3: Via del Garda, 46/L - Tel. 0464913102
A4: ANALISI GRANULOMETRICA (NORMA: UNI CEN ISO/TS 17892-4) | AU4: 38068 - Rovereto (TN)
A5: =Foglio2!A9 -> AUFTRAGGEBER/COMMITT.: | L5: =Foglio2!D9 -> Cantina Produttori Bolzano Soc. Agric. Coop.
A6: =Foglio2!A10 -> BEZUG/RIF.: | H6: =Foglio2!C10 -> 0 | L6: =Foglio2!D10 -> GIR Carlo Ferretti | AI6: =Foglio2!A13 -> BOHRUNG/SONDAGGIO: | AQ6: =Foglio2!D13 -> \
A7: =Foglio2!A11 -> ORT/LOCALITA': | H7: =Foglio2!C11 -> 0 | L7: =Foglio2!D11 -> Bolzano (Bz) | AI7: =Foglio2!A14 -> PROBE/CAMP.: | AQ7: =Foglio2!D14 -> 2_Ei
A8: =Foglio2!A12 -> PROJEKT/PROG.: | H8: =Foglio2!C12 -> 0 | L8: =Foglio2!D12 -> Lagrein 39100 | AI8: =Foglio2!A15 -> TIEFE/PROF. m: | AQ8: =Foglio2!D15 -> \
A9: =Foglio2!A16 -> BESCHREIBUNG/DESCRIZIONE: | L9: =Foglio2!D16 -> Sabbia marrone con limo e con ghiaia arrotondata calcarea
A10: ARGILLA | G10: LIMO | U10: SABBIA | AJ10: GHIAIA | AW10: CIOTTOLI
G11: Fine | K11: Medio | P11: Grosso | U11: Fine | Z11: Medio | AE11: Grosso | AJ11: Fine | AN11: Medio | AS11: Grosso
F12: 0.002 | J12: 0.006 | O12: 0.02 | T12: 0.06 | Y12: 0.2 | AD12: 0.6 | AI12: 2 | AM12: 6 | AR12: 20 | AV12: 60
A39: =Foglio2!A57 -> CERTIFICAZIONE NR: | I39: =Foglio2!E57 -> 22/94
A40: =Foglio2!A58 -> DATA ACCETTAZIONE: | I40: =Foglio2!E58 -> 46080 | AF40: =Foglio2!E61 -> SPERIMENTATORE | AU40: =Foglio2!G61 -> DIRETTORE LABORATORIO
A41: =Foglio2!A59 -> DATA PROVA: | I41: =Foglio2!E59 -> 46085 | AF41: =Foglio2!E62 -> R. Mattuzzi | AU41: =Foglio2!G62 -> dr. F. Shams

Sheet Foglio2
A1: Pag. 2 di 2
A2: VERBALE ACCETTAZIONE NR: 22/27.02.2026 | G2: Geo-Labor s.a.s.
H3: Via del Garda, 46/L - Tel. 0464913102
G4: 38068 - Rovereto (TN)
A5: KORNGRÖßENANALYSE (GEMÄß: UNI CEN ISO/TS 17892-4)
A6: ANALISI GRANULOMETRICA (NORMA: UNI CEN ISO/TS 17892-4)
A7: TABELLA RIASSUNTIVA
A9: AUFTRAGGEBER/COMMITT.: | D9: Cantina Produttori Bolzano Soc. Agric. Coop.
A10: BEZUG/RIF.: | D10: GIR Carlo Ferretti
A11: ORT/LOCALITA': | D11: Bolzano (Bz)
A12: PROJEKT/PROG.: | D12: Lagrein 39100
A13: BOHRUNG/SONDAGGIO: | D13: \
A14: PROBE/CAMP.: | D14: 2_Ei
A15: TIEFE/PROF. m: | D15: \
A16: BESCHREIBUNG/DESCRIZIONE: | D16: Sabbia marrone con limo e con ghiaia arrotondata calcarea
A18: SETACCIATURA
A19: Setaccio | B19: Diametro (mm) | D19: Trattenuto (g) | E19: Trattenuto (%) | F19: Passante (%)
A20: 3 1/2" | B20: 90
A21: 2.1/2" | B21: 63
A22: 2 1/4" | B22: 56
A23: 1 3/4" | B23: 45
A24: 1,1/4" | B24: 31.5 | D24: 0 | E24: =IF(D24="","",SUM($D$20:D24)/$D$38*100) -> 0 | F24: =IF(D24="",F23,100-$E24) -> 100
A25: 7/8" | B25: 22.4 | D25: 116.6 | E25: =IF(D25="","",SUM($D$20:D25)/$D$38*100) -> 2.4173974 | F25: =IF(D25="",F24,100-$E25) -> 97.582603
A26: 5/8" | B26: 16 | D26: 117.2 | E26: =IF(D26="","",SUM($D$20:D26)/$D$38*100) -> 4.8472343 | F26: =IF(D26="",F25,100-$E26) -> 95.152766
A27: 7/16" | B27: 11.2 | D27: 139.4 | E27: =IF(D27="","",SUM($D$20:D27)/$D$38*100) -> 7.7373303 | F27: =IF(D27="",F26,100-$E27) -> 92.26267
A28: 5/16" | B28: 8 | D28: 106.4 | E28: =IF(D28="","",SUM($D$20:D28)/$D$38*100) -> 9.9432573 | F28: =IF(D28="",F27,100-$E28) -> 90.056743
A29: 3.5 | B29: 5.6 | D29: =Foglio4!D21 -> 91.439327 | E29: =IF(D29="","",SUM($D$20:D29)/$D$38*100) -> 11.839014 | F29: =IF(D29="",F28,100-$E29) -> 88.160986
A30: 5 | B30: 4 | D30: =Foglio4!D22 -> 54.542757 | E30: =IF(D30="","",SUM($D$20:D30)/$D$38*100) -> 12.969816 | F30: =IF(D30="",F29,100-$E30) -> 87.030184
A31: 10 | B31: 2 | D31: =Foglio4!D23 -> 212.55633 | E31: =IF(D31="","",SUM($D$20:D31)/$D$38*100) -> 17.376618 | F31: =IF(D31="",F30,100-$E31) -> 82.623382
A32: 18 | B32: 1 | D32: =Foglio4!D24 -> 333.67334 | E32: =IF(D32="","",SUM($D$20:D32)/$D$38*100) -> 24.294466 | F32: =IF(D32="",F31,100-$E32) -> 75.705534
A33: 35 | B33: 0.5 | D33: =Foglio4!D25 -> 467.62393 | E33: =IF(D33="","",SUM($D$20:D33)/$D$38*100) -> 33.98943 | F33: =IF(D33="",F32,100-$E33) -> 66.01057
A34: 60 | B34: 0.25 | D34: =Foglio4!D26 -> 514.94779 | E34: =IF(D34="","",SUM($D$20:D34)/$D$38*100) -> 44.665532 | F34: =IF(D34="",F33,100-$E34) -> 55.334468
A35: 120 | B35: 0.125 | D35: =Foglio4!D27 -> 478.05122 | E35: =IF(D35="","",SUM($D$20:D35)/$D$38*100) -> 54.576679 | F35: =IF(D35="",F34,100-$E35) -> 45.423321
A36: 230 | B36: 0.063 | D36: =Foglio4!D28 -> 439.55045 | E36: =IF(D36="","",SUM($D$20:D36)/$D$38*100) -> 63.689614 | F36: =IF(D36="",F35,100-$E36) -> 36.310386
B37: < 0.063 | D37: =D38-SUM(D20:D36) -> 1751.384 | F37: =D37/D38*100 -> 36.310386
D38: =Foglio4!H13 -> 4823.3691 | E38: Massa secca iniziale (g)
A39: Ciottoli | B39: =E21 -> 0 | D39: % | E39: D10 mm = | F39: 0.007
A40: Ghiaia | B40: =E31-B39 -> 17.376618 | D40: % | E40: D30 mm = | F40: 0.041
A41: Sabbia | B41: =E36-E31 -> 46.312996 | D41: % | E41: D60 mm = | F41: 0.34
A42: Limo | B42: =F37-B43 -> 32.329121 | D42: % | E42: Cu coeff.uniformità | F42: =F41/F39 -> 48.571429
...

Sheet Foglio3
A1: ANALISI GRANULOMETRICA PER SEDIMENTAZIONE
A5: Tempo | B5: Tempe | C5: Lettura | D5: Lettura | E5: Correzione | F5: Diametro | G5: Percentuale | H5: Percentuale
B6: ratura | E6: temperatura | F6: grani | G6: parziale | H6: totale
A7: min | B7: °C | C7: R | D7: R' | F7: mm | G7: % | H7: %
A8: 0.5 | B8: 21.7 | C8: 20.5 | D8: =C8+$C$17 -> 20.7 | E8: =$C$18+$C$19*B8 -> 2.00764 | F8: 0.063 | G8: 100 | H8: =Foglio2!$F$37*G8/100 -> 36.310386
A9: 1 | B9: 21.7 | C9: 19.7 | D9: =C9+$C$17 -> 19.9 | E9: =$C$18+$C$19*B9 -> 2.00764 | F9: =SQRT((1800*(0.0000181/(1+(0.034*B9)+(0.00022*(B9^2)))))*($F$18*D9+$F$17)/(($H$17-1)*(A9*60))) -> 0.046041029 | G9: =(D9+E9+$C$16)*100/$H$16*$H$17/($H$17-1) -> 86.762331 | H9: =Foglio2!$F$37*G9/100 -> 31.503738
A10: 4.5 | B10: 21.7 | C10: 14.2 | D10: =C10+$C$17 -> 14.4 | E10: =$C$18+$C$19*B10 -> 2.00764 | F10: =SQRT((1800*(0.0000181/(1+(0.034*B10)+(0.00022*(B10^2)))))*($F$18*D10+$F$17)/(($H$17-1)*(A10*60))) -> 0.022784134 | G10: =(D10+E10+$C$16)*100/$H$16*$H$17/($H$17-1) -> 61.524235 | H10: =Foglio2!$F$37*G10/100 -> 22.339688
A11: 14 | B11: 21.5 | C11: 10.5 | D11: =C11+$C$17 -> 10.7 | E11: =$C$18+$C$19*B11 -> 1.964 | F11: =SQRT((1800*(0.0000181/(1+(0.034*B11)+(0.00022*(B11^2)))))*($F$18*D11+$F$17)/(($H$17-1)*(A11*60))) -> 0.013345098 | G11: =(D11+E11+$C$16)*100/$H$16*$H$17/($H$17-1) -> 44.345628 | H11: =Foglio2!$F$37*G11/100 -> 16.102069
A12: 54 | B12: 21.8 | C12: 6.8 | D12: =C12+$C$17 -> 7 | E12: =$C$18+$C$19*B12 -> 2.02946 | F12: =SQRT((1800*(0.0000181/(1+(0.034*B12)+(0.00022*(B12^2)))))*($F$18*D12+$F$17)/(($H$17-1)*(A12*60))) -> 0.0069665569 | G12: =(D12+E12+$C$16)*100/$H$16*$H$17/($H$17-1) -> 27.667652 | H12: =Foglio2!$F$37*G12/100 -> 10.046231
A13: 120 | B13: 21.3 | C13: 5.1 | D13: =C13+$C$17 -> 5.3 | E13: =$C$18+$C$19*B13 -> 1.92036 | F13: =SQRT((1800*(0.0000181/(1+(0.034*B13)+(0.00022*(B13^2)))))*($F$18*D13+$F$17)/(($H$17-1)*(A13*60))) -> 0.0047605085 | G13: =(D13+E13+$C$16)*100/$H$16*$H$17/($H$17-1) -> 19.366154 | H13: =Foglio2!$F$37*G13/100 -> 7.0319254
A14: 360 | B14: 20.3 | C14: 4.1 | D14: =C14+$C$17 -> 4.3 | E14: =$C$18+$C$19*B14 -> 1.70216 | F14: =SQRT((1800*(0.0000181/(1+(0.034*B14)+(0.00022*(B14^2)))))*($F$18*D14+$F$17)/(($H$17-1)*(A14*60))) -> 0.0028018067 | G14: =(D14+E14+$C$16)*100/$H$16*$H$17/($H$17-1) -> 13.776145 | H14: =Foglio2!$F$37*G14/100 -> 5.0021716
A15: 1440 | B15: 20.9 | C15: 2.9 | D15: =C15+$C$17 -> 3.1 | E15: =$C$18+$C$19*B15 -> 1.83308 | F15: =SQRT((1800*(0.0000181/(1+(0.034*B15)+(0.00022*(B15^2)))))*($F$18*D15+$F$17)/(($H$17-1)*(A15*60))) -> 0.0014028034 | G15: =(D15+E15+$C$16)*100/$H$16*$H$17/($H$17-1) -> 8.8704104 | H15: =Foglio2!$F$37*G15/100 -> 3.2208803
A16: correzione per il dispersivo | B16: Cd | C16: -3 | E16: taratura densimetro | G16: Peso Campione in g | H16: 35
A17: correzione per il menisco | B17: Cm | C17: 0.2 | D17: intercetta | F17: 16.239 | G17: Gs g/cm3 | H17: 2.65 | I17: (valore stimato)
A18: correzione per la temperatura | B18: Ct intercetta | C18: -2.7273 | D18: pendenza | F18: -0.22
B19: Ct pendenza | C19: 0.2182
A22: CALCOLO %TOT A 0,002mm
A23: differenza diam grani | C23: =F14-F15 -> 0.0013990033
A24: differenza % tot | C24: =H14-H15 -> 1.7812914
A26: pendenza | C26: =C24/C23 -> 1273.2574
A27: intercetta | C27: =H14-(C26*F14) -> 1.4347504
A29: % a 0,002mm | C29: =C26*0.002+C27 -> 3.9812653

Sheet Foglio4
A4: DETERMINAZIONE DELLA GRANULOMETRIA DI UN AGGREGATO
A5: Norma UNI EN 933-1, UNI CEN ISO TS 17892-4
A8: =Foglio2!A2 -> VERBALE ACCETTAZIONE NR: 22/27.02.2026 | G8: Data arrivo______________ | H8: =Foglio2!E58 -> 46080
D9: Campione____________ | E9: =Foglio2!D14 -> 2_Ei
A10: Sperimentatore_________________ | G10: Data prove______________
A13: Quantità del campione in prova: | G13: m 1 PNS: | H13: =H14+H15 -> 4823.3691
A14: Massa della frazione grossa ≥ 8,00 mm.: | G14: m 2 PNS: | H14: =SUM(Foglio2!D20:D28) -> 479.6
A15: Massa della frazione fine ≤ 8,00 mm: | E15: 7 | F15: =E46 -> 4336.7691 | G15: m 3 PNS: | H15: =E15+F15 -> 4343.7691
A16: Massa del campione ottenuto dopo quartatura: | G16: m 4 PNS: | H16: 1083.1
A19: Setaccio | B19: Massa trattenuta | E19: Note
A20: mm. | B20: M (g) | D20: M. tot. (A) g
A21: 5.6 | B21: 22.8 | D21: =B21*($H$15/$H$16) -> 91.439327
A22: 4 | B22: 13.6 | D22: =B22*($H$15/$H$16) -> 54.542757
A23: 2 | B23: 53 | D23: =B23*($H$15/$H$16) -> 212.55633 | E23: Ridurre il passante allo staccio ≤ 8,00 a circa 1000 gr
A24: 1 | B24: 83.2 | D24: =B24*($H$15/$H$16) -> 333.67334 | E24: (solo se il passante è maggiore di 1000 grammi)
A25: 0.5 | B25: 116.6 | D25: =B25*($H$15/$H$16) -> 467.62393
A26: 0.25 | B26: 128.4 | D26: =B26*($H$15/$H$16) -> 514.94779
A27: 0.125 | B27: 119.2 | D27: =B27*($H$15/$H$16) -> 478.05122
A28: 0.063 | B28: 109.6 | D28: =B28*($H$15/$H$16) -> 439.55045
A29: ≤ 0,063 | B29: =H16-SUM(B21:C28) -> 436.7 | D29: =B29*($H$15/$H$16) -> 1751.384 | E29: (A): Massa totale trattenuta a ciascun setaccio:
A30: Somma g | E30: M*(M3/M4) = M tot.
A31: Perdita g
A33: PNU > 8mm: | C33: 498.7 | G33: PNU Quartato < 8mm: | H33: 1239.5
A34: PNU < 8mm: | C34: 4963 | G34: PLU Quartato < 8mm: | H34: =H33+H35 -> 1630
C35: =C33+C34 -> 5461.7 | G35: tara: | H35: 390.5
G36: PLS Quartato < 8mm: | H36: =H16+H35 -> 1473.6
A37: Note:___________________________________________________________________________________
H39: %W < 8 mm = | I39: =((H33-H16)/(H16)) -> 0.14440033
H40: %W totale = | I40: =(C35-H13)/H13 -> 0.13234129
B41: Calcolo proporzione per Tot. SECCO <8mm =
B43: PNU < 8mm X m 4 PNS | D43: = | E43: Massa della frazione fine < 8,00 mm
B44: PNU Quartato < 8mm
C46: =C34*H16 -> 5375425.3 | D46: = | E46: =C46/C47 -> 4336.7691
C47: =H33 -> 1239.5
A50: gra-terre 0-8 | H50: Geo-Labor sas
