Workbook

Sheet Foglio1
A1: Pag. 1 di 2 | AP1: Geo-Labor s.a.s.
A2: =Foglio2!A2 -> VERBALE ACCETTAZIONE NR: 19/24.02.2026 | W2: =Foglio2!E8 -> Classificazione Generale UNI-EN 12620
A3: KORNGROSSENANALYSE (GEMÄß: UNI EN 933-1) | W3: =Foglio2!E9 -> Categoria: GF 85 | AG3: =Foglio2!F9 -> Fini: f3 | AT3: Via del Garda, 46/L-Tel. 0464913102
A4: ANALISI GRANULOMETRICA (NORME: UNI EN 933-1) | AT4: 38068 - Rovereto (TN)
A5: =Foglio2!A11 -> AUFTRAGGEBER/COMMITT.: | L5: =Foglio2!D11 -> ANTON MAIER G.m.b.H/S.r.l. | AA5: =Foglio2!A14 -> PROBE/CAMP.: | AH5: =Foglio2!D14 -> Cod. 010
A6: =Foglio2!A12 -> ORT/LOCALITA': | H6: =Foglio2!C12 -> 0 | L6: =Foglio2!D12 -> Schotterwerk Bozen/inerti Bolzano | AH6: =Foglio2!D15 -> DENOMINAZIONE: Aggregato fine naturale | AW6: =Foglio2!G15 -> 0/4 mm
A7: =Foglio2!A13 -> PROJEKT/PROGETTO: | L7: =Foglio2!D13 -> Classificazione aggregati per calcestruzzo | AH7: =Foglio2!D16 -> DESIGNAZIONE: Aggregato fine naturale | AW7: =Foglio2!G16 -> 0/4 mm
A8: =Foglio2!A18 -> BESCHREIBUNG/DESCRIZIONE: | L8: =Foglio2!D18 -> sabbia di natura porfirica di colore marrone con ghiaino spigoloso prev. porfido
A9: ARGILLA | G9: LIMO | T9: SABBIA | AI9: GHIAIA | AV9: CIOTTOLI
G10: Fine | K10: Medio | O10: Grosso | T10: Fine | Y10: Medio | AD10: Grosso | AI10: Fine | AM10: Medio | AR10: Grosso
F11: 0.002 | J11: 0.006 | S11: 0.06 | X11: 0.2 | AC11: 0.6 | AH11: 2 | AL11: 6 | AQ11: 20 | AU11: 60
A39: =Foglio2!A50 -> BESCHEINIGUNG/CERTIFICAZIONE NR.: | N39: =Foglio2!E50 -> 19/85
A40: =Foglio2!A51 -> ANNAHMEDATUM/DATA ACCETTAZIONE: | N40: =Foglio2!E51 -> 46077 | X40: =Foglio2!D55 -> SPERIMENTATORE | AM40: =Foglio2!F55 -> DIRETTORE LABORATORIO
A41: =Foglio2!A52 -> VERSUCH DATUM/DATA PROVA : | N41: =Foglio2!E52 -> 46083 | Y41: =Foglio2!D56 -> R. Mattuzzi | AM41: =Foglio2!F56 -> dr. F. Shams

Sheet Foglio2
A1: Pag. 2 di 2 | F1: Geo-Labor s.a.s.
A2: VERBALE ACCETTAZIONE NR: 19/24.02.2026
G3: Via del Garda, 46/L-Tel. 0464913102
G4: 38068 - Rovereto (TN)
A5: KORNGROSSENANALYSE (GEMÄß: UNI EN 933-1)
A6: ANALISI GRANULOMETRICA (NORME: UNI EN 933-1)
A8: TABELLA RIASSUNTIVA | E8: Classificazione Generale UNI-EN 12620
E9: Categoria: GF 85 | F9: Fini: f3
A11: AUFTRAGGEBER/COMMITT.: | D11: ANTON MAIER G.m.b.H/S.r.l.
A12: ORT/LOCALITA': | D12: Schotterwerk Bozen/inerti Bolzano
A13: PROJEKT/PROGETTO: | D13: Classificazione aggregati per calcestruzzo
A14: PROBE/CAMP.: | D14: Cod. 010
D15: DENOMINAZIONE: Aggregato fine naturale | G15: 0/4 mm
D16: DESIGNAZIONE: Aggregato fine naturale | G16: 0/4 mm
A18: BESCHREIBUNG/DESCRIZIONE: | D18: sabbia di natura porfirica di colore marrone con ghiaino spigoloso prev. porfido
F20: (prelievo del 24.02.2026)
A21: SIEBUG/SETACCIATURA
A22: Sieb | B22: Durchmesser | D22: Rückstand | E22: Rückstand | F22: Durchgang
A23: Setaccio | B23: Diametro (mm) | D23: Trattenuto (g) | E23: Trattenuto (%) | F23: Passante (%)
A24: 3. 1/2" | B24: 90 | E24: =IF(D24="","",SUM($D$24:D24)/$D$42*100)
A25: 2. 1/2" | B25: 63
A26: 2. 1/4" | B26: 56 | E26: =IF(D26="","",SUM($D$24:D26)/$D$42*100)
A27: 1. 3/4" | B27: 45 | E27: =IF(D27="","",SUM($D$24:D27)/$D$42*100)
A28: 1.1/4" | B28: 31.5 | E28: =IF(D28="","",SUM($D$24:D28)/$D$42*100)
A29: 7/8" | B29: 22.4 | E29: =IF(D29="","",SUM($D$24:D29)/$D$42*100)
A30: 5/8" | B30: 16
A31: 7/16" | B31: 11.2
A32: 5/16" | B32: 8 | D32: 0 | E32: =IF(D32="","",SUM($D$24:D32)/$D$42*100) -> 0 | F32: =IF(D32="",F31,100-$E32) -> 100
A33: 3.5 | B33: 5.6 | D33: 9.8 | E33: =IF(D33="","",SUM($D$24:D33)/$D$42*100) -> 0.66328257 | F33: =IF(D33="",F32,100-$E33) -> 99.336717
A34: 5 | B34: 4 | D34: 65 | E34: =IF(D34="","",SUM($D$24:D34)/$D$42*100) -> 5.0626058 | F34: =IF(D34="",F33,100-$E34) -> 94.937394
A35: 10 | B35: 2 | D35: 383.6 | E35: =IF(D35="","",SUM($D$24:D35)/$D$42*100) -> 31.025381 | F35: =IF(D35="",F34,100-$E35) -> 68.974619
A36: 18 | B36: 1 | D36: 333.8 | E36: =IF(D36="","",SUM($D$24:D36)/$D$42*100) -> 53.617597 | F36: =IF(D36="",F35,100-$E36) -> 46.382403
A37: 35 | B37: 0.5 | D37: 252.6 | E37: =IF(D37="","",SUM($D$24:D37)/$D$42*100) -> 70.714044 | F37: =IF(D37="",F36,100-$E37) -> 29.285956
A38: 60 | B38: 0.25 | D38: 200.6 | E38: =IF(D38="","",SUM($D$24:D38)/$D$42*100) -> 84.291032 | F38: =IF(D38="",F37,100-$E38) -> 15.708968
A39: 120 | B39: 0.125 | D39: 130.6 | E39: =IF(D39="","",SUM($D$24:D39)/$D$42*100) -> 93.130288 | F39: =IF(D39="",F38,100-$E39) -> 6.8697124
A40: 230 | B40: 0.063 | D40: 77.4 | E40: =IF(D40="","",SUM($D$24:D40)/$D$42*100) -> 98.368866 | F40: =IF(D40="",F39,100-$E40) -> 1.6311337
B41: < 0.063 | D41: =D42-SUM(D24:D40) -> 24.1 | F41: =D41/D42*100 -> 1.6311337
A42: Trockenmasse (g) | D42: 1477.5
A43: Steine/Ciottoli | B43: =E25 -> 0 | D43: % | E43: Dimensioni
A44: Kies/Ghiaia | B44: =E35-B43 -> 31.025381 | D44: %
...
